<mujoco model="bouncing_ball">
    <compiler angle="radian" coordinate="local" inertiafromgeom="true"/>
    <option gravity="0 0 -9.81" timestep="0.01"/>
    
    <default>
        <joint armature="1" damping="1" limited="true"/>
        <geom conaffinity="0" condim="3" density="5.0" friction="1 0.5 0.5" margin="0.01"/>
    </default>

    <worldbody>
        <light diffuse=".5 .5 .5" pos="0 0 3" dir="0 0 -1"/>
        <geom name="floor" pos="0 0 0" size="1 1 .01" type="plane" material="grid"/>
        
        <!-- Bouncing ball with initial height of 1m -->
        <body name="ball" pos="0 0 1">
            <joint name="ball_z" type="slide" axis="0 0 1" pos="0 0 0" limited="false"/>
            <geom name="ball_geom" type="sphere" size="0.01" mass="0.1" rgba="1 0 0 1"/>
        </body>
    </worldbody>

    <actuator>
        <!-- Force actuator in z-direction -->
        <motor joint="ball_z" name="z_motor" gear="1" ctrllimited="true" ctrlrange="-1 1"/>
    </actuator>

    <asset>
        <texture type="skybox" builtin="gradient" rgb1="0.3 0.5 0.7" rgb2="0 0 0" width="512" height="512"/>
        <texture name="grid" type="2d" builtin="checker" rgb1=".1 .2 .3" rgb2=".2 .3 .4" width="300" height="300" mark="edge" markrgb=".2 .3 .4"/>
        <material name="grid" texture="grid" texrepeat="1 1" texuniform="true" reflectance=".2"/>
    </asset>
</mujoco> 